tests/data/fixture-snapshot.txt
# end-of-replay book snapshot
# level lines: side price total_qty order_count (price has 4 implied decimals)
stock AAPL locate 14 levels 5362 orders 39806
B 1623300 900 1
B 1623200 700 3
B 1623100 600 1
B 1623000 1142 6
B 1622900 3100 3
B 1622800 800 3
B 1622700 712 3
B 1622600 730 3
B 1622500 612 6
B 1622400 630 3
B 1622300 712 4
B 1622200 830 4
B 1622100 712 5
B 1622000 700 2
B 1621900 642 3
B 1621800 900 4
B 1621700 850 5
B 1621600 200 2
B 1621500 120 2
B 1621400 600 2
B 1621300 500 2
B 1621200 100 1
B 1621100 200 2
B 1620800 10 1
B 1620700 100 1
B 1620600 200 1
B 1620200 20 1
B 1620000 453 7
B 1619900 400 1
B 1619600 500 2
B 1619500 100 1
B 1619200 200 2
B 1619000 8 2
B 1618700 100 1
B 1618600 100 1
B 1618500 220 2
B 1618100 100 1
B 1618000 3494 13
B 1617900 1315 4
B 1617800 50 1
B 1617700 126 4
B 1617500 3105 8
B 1617400 40 1
B 1617300 100 1
B 1617200 600 1
B 1617000 646 7
B 1616900 1625 3
B 1616700 3000 1
B 1616600 601 2
B 1616500 641 6
B 1616400 200 1
B 1616200 3500 2
B 1616100 700 2
B 1616000 445 4
B 1615900 100 1
B 1615800 200 1
B 1615700 4500 4
B 1615600 78 1
B 1615500 1100 4
B 1615100 1825 5
B 1615000 6628 33
B 1614800 200 1
B 1614700 2 1
B 1614500 12 1
B 1614400 550 2
B 1614200 11 2
B 1614100 9 1
B 1614000 400 2
B 1613600 7 1
B 1613500 150 2
B 1613300 100 1
B 1613200 100 1
B 1613000 912 4
B 1612800 150 2
B 1612700 1005 2
B 1612600 100 1
B 1612500 2725 8
B 1612400 100 1
B 1612300 100 1
B 1612000 261 7
B 1611700 500 1
B 1611600 500 1
B 1611500 300 1
B 1611400 100 1
B 1611200 500 1
B 1611100 150 1
B 1611000 1990 8
B 1610700 1000 1
B 1610600 100 1
B 1610500 780 5
B 1610300 111 3
B 1610200 700 2
B 1610100 45 1
B 1610000 16946 97
B 1609900 60 1
B 1609800 436 2
B 1609500 1151 4
B 1609200 200 1
B 1608800 455 4
B 1608600 170 2
B 1608100 500 1
B 1608000 1735 6
B 1607500 261 4
B 1607300 1 1
B 1607100 75 1
B 1607000 650 3
B 1606800 30 1
B 1606600 51 2
B 1606500 100 1
B 1606300 47 1
B 1606000 123 4
B 1605900 5 1
B 1605800 25 1
B 1605700 220 3
B 1605600 900 1
B 1605500 762 5
B 1605300 150 1
B 1605200 73 2
B 1605100 526 3
B 1605000 6060 28
B 1604500 305 2
B 1604300 250 1
B 1604000 2161 9
B 1603900 100 1
B 1603800 210 2
B 1603600 8 1
B 1603500 450 2
B 1603400 500 1
B 1603300 150 1
B 1603100 200 1
B 1603000 15 1
B 1602700 250 2
B 1602500 420 2
B 1602400 400 1
B 1602300 135 1
B 1602200 4 2
B 1602000 1756 11
B 1601800 10 1
B 1601500 31 3
B 1601400 4 1
B 1601300 40 1
B 1601100 910 3
B 1601000 2814 11
B 1600800 50 1
B 1600700 200 1
B 1600600 325 2
B 1600500 1366 6
B 1600300 60 2
B 1600200 319 3
B 1600100 767 6
B 1600000 28651 307
B 1599900 3239 9
B 1599800 300 4
B 1599600 503 2
B 1599500 1045 6
B 1599200 303 2
B 1599000 823 7
B 1598900 100 1
B 1598800 536 4
B 1598500 200 3
B 1598300 2 1
B 1598000 1292 6
B 1597800 22 2
B 1597600 20 1
B 1597500 674 6
B 1597400 15 1
B 1597000 2470 8
B 1596700 75 1
B 1596600 100 1
B 1596500 200 2
B 1596100 50 1
B 1596000 126 2
B 1595800 30 1
B 1595700 200 1
B 1595500 152 4
B 1595200 60 1
B 1595000 2404 17
B 1594500 100 1
B 1594300 200 1
B 1594000 559 4
B 1593800 150 1
B 1593700 1 1
B 1593600 20 1
B 1593500 70 2
B 1593000 765 6
B 1592900 300 1
B 1592500 119 4
B 1592000 100 1
B 1591900 25 1
B 1591800 60 1
B 1591500 100 1
B 1591400 300 1
B 1591100 100 1
B 1591000 191 5
B 1590900 200 1
B 1590600 20 1
B 1590500 950 3
B 1590300 95 2
B 1590100 606 4
B 1590000 12026 99
B 1589900 400 2
B 1589800 83 2
B 1589500 100 1
B 1588900 120 2
B 1588800 920 4
B 1588500 516 2
B 1588100 20 1
B 1588000 1048 4
B 1587700 1 1
B 1587500 35 2
B 1587400 50 1
B 1587000 160 3
B 1586700 100 1
B 1586600 100 1
B 1586500 50 1
B 1586000 40 2
B 1585600 200 2
B 1585500 2350 4
B 1585200 100 1
B 1585100 100 1
B 1585000 2899 22
B 1584600 45 1
B 1584500 37 3
B 1584400 2 1
B 1584100 150 2
B 1584000 30 1
B 1583700 30 1
B 1583600 17 2
B 1583500 100 1
B 1583000 30 1
B 1582600 7 1
B 1582500 1820 4
B 1582300 235 4
B 1582100 25 1
B 1582000 126 5
B 1581900 350 1
B 1581800 250 3
B 1581500 320 2
B 1581400 1 1
B 1581300 1 1
B 1581200 225 2
B 1581000 35 2
B 1580900 50 1
B 1580800 150 1
B 1580700 115 2
B 1580500 187 5
B 1580200 5 1
B 1580100 507 2
B 1580000 26152 160
B 1579800 350 2
B 1579600 20 1
B 1579000 132 2
B 1578900 50 1
B 1578700 100 1
B 1578600 12 2
B 1578500 25 1
B 1578000 91 2
B 1577900 10 1
B 1577700 449 2
B 1577500 150 2
B 1577000 4 1
B 1576900 100 1
B 1576800 50 1
B 1576000 400 2
B 1575700 40 2
B 1575600 82 1
B 1575500 30 1
B 1575000 1318 16
B 1574600 100 1
B 1574500 100 1
B 1574400 100 1
B 1574300 100 1
B 1573800 150 1
B 1573500 10 1
B 1573300 30 2
B 1573200 100 1
B 1572800 100 1
B 1572500 1220 4
B 1572200 6 1
B 1572100 100 1
B 1572000 1100 1
B 1571500 2 1
B 1571300 100 1
B 1571000 275 3
B 1570800 61 1
B 1570100 1003 2
B 1570000 17442 71
B 1569900 20 1
B 1569800 75 2
B 1569500 200 2
B 1568800 300 3
B 1567800 505 2
B 1567500 100 1
B 1567400 100 1
B 1567100 327 4
B 1567000 45 1
B 1566800 150 2
B 1566500 100 1
B 1566000 10 1
B 1565600 7 1
B 1565500 80 1
B 1565000 715 10
B 1564000 274 4
B 1563300 3 1
B 1563200 1000 1
B 1563000 56 1
B 1562500 153 3
B 1562000 209 2
B 1561800 65 1
B 1561500 800 1
B 1561200 700 1
B 1561000 30 1
B 1560900 100 1
B 1560600 1050 1
B 1560500 50 1
B 1560100 1134 3
B 1560000 7623 98
B 1559100 79 2
B 1559000 40 1
B 1558900 100 1
B 1558800 7 1
B 1558100 10 1
B 1557700 350 3
B 1557500 135 2
B 1556800 100 1
B 1556600 40 1
B 1556400 400 4
B 1556200 100 1
B 1556000 61 3
B 1555800 100 1
B 1555500 236 4
B 1555000 932 11
B 1554900 267 73
B 1554500 570 3
B 1554000 641 3
B 1552900 400 1
B 1552600 37 1
B 1552500 582 4
B 1552200 100 1
B 1552100 300 1
B 1552000 29 2
B 1551800 9 1
B 1551700 200 1
B 1551500 9 1
B 1551100 100 2
B 1551000 139 3
B 1550900 300 1
B 1550800 200 2
B 1550500 110 2
B 1550200 451 3
B 1550100 92 3
B 1550000 26380 303
B 1549900 20 1
B 1549700 495 1
B 1549600 6 1
B 1549500 108 3
B 1549300 700 1
B 1549200 400 1
B 1549000 191 6
B 1548900 1 1
B 1548800 622 6
B 1548700 40 1
B 1548500 1 1
B 1548100 1071 2
B 1548000 292 7
B 1547900 20 1
B 1547700 221 3
B 1547600 26 1
B 1547500 138 6
B 1547200 36 1
B 1547100 60 1
B 1547000 1042 20
B 1546900 54 6
B 1546800 6261 114
B 1546700 3 1
B 1546600 4 1
B 1546500 133 4
B 1546400 20 1
B 1546100 10 1
B 1546000 363 24
B 1545800 68 4
B 1545700 93 1
B 1545500 70 2
B 1545400 8 1
B 1545100 10 1
B 1545000 2217 27
B 1544800 100 1
B 1543400 41 1
B 1543100 10 1
B 1543000 6 1
B 1542900 226 4
B 1542500 100 1
B 1542400 240 1
B 1542000 101 2
B 1541900 10 1
B 1541500 60 2
B 1541200 4 1
B 1541100 1 1
B 1541000 1180 3
B 1540800 150 1
B 1540600 200 1
B 1540500 50 1
B 1540300 10 1
B 1540200 25 1
B 1540000 11127 152
B 1539900 9 1
B 1539200 6 1
B 1539100 100 1
B 1539000 34 3
B 1538900 10 1
B 1538800 28 2
B 1538100 15 1
B 1538000 105 6
B 1537900 169 1
B 1537700 120 2
B 1537600 465 1
B 1537500 394 9
B 1537400 200 1
B 1537000 770 5
B 1536900 18 1
B 1536800 363 4
B 1536600 60 1
B 1536500 1 1
B 1536000 38 8
B 1535500 650 3
B 1535300 2 1
B 1535100 15 1
B 1535000 1484 20
B 1534600 100 1
B 1534400 200 2
B 1533900 100 1
B 1533700 15 1
B 1533400 55 2
B 1533300 100 1
B 1533000 55 3
B 1532700 11 1
B 1532500 1589 7
B 1532300 65 1
B 1532000 190 4
B 1531900 10 1
B 1531600 540 2
B 1531500 100 1
B 1531300 25 1
B 1531200 12 1
B 1531100 135 2
B 1530800 400 1
B 1530700 50 1
B 1530600 15 2
B 1530500 1 1
B 1530300 20 1
B 1530100 50 3
B 1530000 11703 143
B 1529900 120 1
B 1529600 300 2
B 1529100 5 1
B 1529000 153 4
B 1528800 288 2
B 1528500 123 2
B 1528000 369 6
B 1527900 1 1
B 1527800 3 2
B 1527500 410 5
B 1527400 50 1
B 1527300 35 1
B 1527200 27 2
B 1527100 3 1
B 1527000 244 8
B 1526900 46 1
B 1526800 50 1
B 1526500 5 2
B 1526400 8 1
B 1526300 50 1
B 1526200 300 3
B 1526000 31 2
B 1525900 10 1
B 1525800 1 1
B 1525500 180 3
B 1525300 500 1
B 1525200 115 4
B 1525100 104 3
B 1525000 3153 26
B 1524900 41 1
B 1524400 50 1
B 1524200 3 1
B 1524000 45 1
B 1523800 20 1
B 1523600 3 1
B 1523500 20 1
B 1523200 20 1
B 1523100 150 1
B 1523000 97 3
B 1522800 83 2
B 1522500 159 4
B 1522300 25 1
B 1522100 10 1
B 1522000 73 4
B 1521700 100 1
B 1521500 30 2
B 1521400 129 2
B 1521200 100 1
